Workbook
Name TotalManHours: ManHours!$I$5
Name LTIFR: Dashboard!$E$7
Name TRIFR: Dashboard!$G$7
Name AdminPassword: Cover!$C$14

Sheet Cover
A1: KAZ PP EXPANSION PROJECT | EHS MANAGEMENT SYSTEM
A2: Integrated Occupational Health, Safety & Environment Control Workbook | OSHA KPIs | Confidential
B4: SYSTEM IDENTITY | H4: QUICK STATUS
B5: Project Name | C5: KAZ PP Expansion Project | H5: Today | I5: =TODAY()
B6: Client / Owner | C6: As per Contract | H6: File Rev | I6: 00
B7: Main Contractor | C7: Team Seisms / Team Al-Mayal Consortium | H7: Macro Pack | I7: Import VBA_EHS_Module.bas
B8: Document Title | C8: Integrated EHS Management & Evaluation System | H8: Language | I8: EN / AR bilingual labels
B9: Document No. | C9: KAZ-EHS-SYS-001 Rev.00
B10: Classification | C10: CONFIDENTIAL — Controlled Document
B11: Prepared by | C11: EHS Department — Project Control
B12: Admin Owner | C12: EHS Manager (Full Control)
B13: Effective Date | C13: 46023
B14: Workbook Password (Admin) | C14: KAZ-EHS-ADMIN-2026
B16: WORKSHEET MAP | هيكل الشيتات
B17: Sheet | C17: Purpose / الغرض
B18: 00_Cover | C18: الغلاف والتعريف والصلاحيات
B19: 01_Dashboard | C19: لوحة التحكم ومؤشرات OSHA / KPIs
B20: 02_ManHours | C20: حاسبة ساعات العمل اليومية (Seisms / Al-Mayal)
B21: 03_Incidents | C21: سجل الحوادث والإصابات و Near Miss
B22: 04_Observations | C22: تتبع الملاحظات + Aging + PTW
B23: 05_NCR | C23: إخطارات عدم المطابقة NCR
B24: 06_Scorecard | C24: تقييم أداء المقاولين الثانويين
B25: 07_CAPA_AI | C25: محور تحويل الملاحظات والإجراءات التصحيحية
B26: 08_Training | C26: مصفوفة شهادات العمالة الماهرة
B27: 09_Equipment | C27: تفتيش المعدات الثقيلة وشهادات الطرف الثالث
B28: 10_Documents | C28: مستودع الوثائق والسير الذاتية والخطط
... B30: 12_Admin | C30: إعدادات النظام، الأهداف، البريد، الحماية
B32: OSHA FORMULAS USED IN THIS SYSTEM
B33: LTIFR (Lost Time Injury Frequency Rate) = (Number of LTIs × 1,000,000) / Total Man-Hours
B34: TRIFR (Total Recordable Injury Frequency Rate) = (Recordable Cases × 1,000,000) / Total Man-Hours
B35: Severity Rate (optional) = (Lost Workdays × 1,000,000) / Total Man-Hours
B36: Man-Hours without LTI = Cumulative man-hours since last LTI date (auto from 02_ManHours & 03_Incidents)
B38: SECURITY: Protect workbook & sheets with the Admin password shown above. Yellow cells = INPUT (unlocked). Blue cells = CALCULATED (locked). Import VBA_EHS_Module.bas via Alt+F11 → File → Import. Enable macros. Outlook must be installed for email alerts. Default password: KAZ-EHS-ADMIN-2026 — change it immediately after first open.

Sheet Dashboard
A1: 01 | EHS DASHBOARD & KPIs — KAZ PP EXPANSION PROJECT
A2: Live OSHA rates, man-hours without LTI, case counters, observation aging, contractor scores. Calculated cells are locked.
B4: Report date | C4: =TODAY() | D4: Total Man-Hours | E4: =ManHours!I5 | F4: Last LTI | G4: =IF(Admin!C31<>"",Admin!C31,IF(Incidents!W13="None","None",Incidents!W13))
B6: MAN-HOURS w/o LTI | E6: LTIFR | G6: TRIFR | I6: EHS PERFORMANCE SCORE | L6: PERFORMANCE BAND
B7: =IF(OR(G4="None",G4=""),E4,SUMIF(ManHours!B8:B400,">"&N(G4),ManHours!M8:M400)) | E7: =IF(E4=0,0,Incidents!W10*Admin!C7/E4) | G7: =IF(E4=0,0,Incidents!W9*Admin!C7/E4) | I7: =MAX(Admin!C22,MIN(100,Admin!C21+Incidents!W10*Admin!C18+Incidents!W9*Admin!C19+NCR!R4*Admin!C17+Observations!W9*Admin!C16+Observations!W6*Admin!C15+Incidents!W5*Admin!C20)) | L7: =IF(I7>=Admin!C36,"A — EXCELLENT",IF(I7>=Admin!C37,"B — SATISFACTORY",IF(I7>=Admin!C38,"C — NEEDS IMPROVEMENT","D — UNSATISFACTORY")))
B8: Target LTIFR | C8: =Admin!C8 | E8: vs Target | F8: =IF(E7<=Admin!C8,"ON TARGET","ABOVE TARGET") | G8: vs Target | H8: =IF(G7<=Admin!C9,"ON TARGET","ABOVE TARGET")
B10: CASE & OBSERVATION COUNTERS (auto from registers)
B11: Near Miss | D11: Unsafe Acts | F11: Unsafe Conditions | H11: First Aid | J11: Recordable | L11: LTI
B12: =Incidents!W5 | D12: =Incidents!W6 | F12: =Incidents!W7 | H12: =Incidents!W8 | J12: =Incidents!W9 | L12: =Incidents!W10
B13: NCR Open | D13: OBS Open | F13: OBS Overdue | H13: OBS Critical open | J13: Cert Expired/Crit. | L13: Equip Quarantine+
B14: =NCR!R4 | D14: =Observations!W6 | F14: =Observations!W9 | H14: =Observations!W10 | J14: =Training!Q4 | L14: =COUNTIF(Equipment!M5:M60,"QUARANTINE / EXPIRED")+COUNTIF(Equipment!M5:M60,"CRITICAL ≤7d")
B16: MAN-HOURS SPLIT | H16: TOP OVERDUE OBSERVATIONS (aging)
B17: Team Seisms | C17: =ManHours!C5 | D17: Team Al-Mayal | E17: =ManHours!E5 | H17: Use sheet Observations, sort by Overdue Days. Open items escalate every calendar day until Closed.
B18: Indirect | C18: =ManHours!G5 | D18: Unified Total | E18: =ManHours!I5
B20: LIFE-SAVING FOCUS AREAS (from observation types — count)
B21: Type | C21: Count
B22: Lifting Operations | C22: =COUNTIF(Observations!$D$5:$D$250,B22)
B23: Working at Height | C23: =COUNTIF(Observations!$D$5:$D$250,B23)
B24: Excavation | C24: =COUNTIF(Observations!$D$5:$D$250,B24)
B25: Scaffolding | C25: =COUNTIF(Observations!$D$5:$D$250,B25)
B26: Confined Space | C26: =COUNTIF(Observations!$D$5:$D$250,B26)
B27: Electrical | C27: =COUNTIF(Observations!$D$5:$D$250,B27)
B28: Work Permits / PTW | C28: =COUNTIF(Observations!$D$5:$D$250,B28)
B31: MACRO ACTIONS (after importing VBA_EHS_Module.bas): EHS_SendCriticalAlert | EHS_SendNCRAlert | EHS_ExportWeeklyPDF | EHS_ProtectAll | EHS_UnprotectAll | EHS_RefreshAging

Sheet Lookups
A1: 11 | LOOKUP TABLES & CLASSIFICATIONS
A2: Do not delete named lists. Used by data validation across the workbook.
B4: Observation Types | C4: Status | D4: Severity | E4: Subcontractors | F4: Incident Class | G4: Trade / Certificate Type | H4: Equipment Type | I4: Teams | J4: Shift
B5: Lifting Operations | C5: Open | D5: Low | E5: Team Seisms | F5: Near Miss | G5: Crane Operator | H5: Mobile Crane | I5: Team Seisms | J5: Day
B6: Confined Space | C6: In Progress | D6: Medium | E6: Team Al-Mayal | F6: Unsafe Act | G6: Rigger / Banksman | H6: Tower Crane | I6: Team Al-Mayal | J6: Night
B7: Excavation | C7: Closed | D7: High | E7: Civil Subcontractor A | F7: Unsafe Condition | G7: First Aider / EMT | H7: MEWP / Manlift | I7: Shared / Indirect | J7: Double
B8: Scaffolding | C8: Overdue | D8: Critical | E8: Mechanical Subcontractor B | F8: First Aid | G8: Welder | H8: Forklift
B9: Working at Height | E9: Electrical Subcontractor C | F9: Medical Treatment (MTC) | G9: Scaffolder | H9: Excavator
B10: Electrical | E10: Scaffolding Contractor D | F10: Restricted Work (RWC) | G10: Electrician | H10: Loader
B11: Work Permits / PTW | E11: Lifting Contractor E | F11: Lost Time Injury (LTI) | G11: Confined Space Entrant | H11: Dump Truck
B12: Hot Work | E12: Security Contractor F | F12: Recordable Case | G12: H2S / BA User | H12: Generator
B13: Housekeeping | F13: Property Damage | G13: Forklift Operator | H13: Compressor
B14: PPE | F14: Environmental Incident | G14: Excavator Operator | H14: Welding Machine
B15: Traffic / Vehicles | F15: Security Incident | G15: Fire Watch | H15: Scaffold Tower
B16: Chemical / HAZMAT | F16: Fatality | G16: EHS Officer | H16: Lifting Gear (slings/shackles)
B17: Fire Prevention | G17: EHS Supervisor
B18: Environmental | G18: EHS Manager
B19: Security | G19: PTW Receiver
B20: Welfare | G20: Authorized Gas Tester
B21: Barricades / Signage
B22: Tools & Equipment
B23: Energy Isolation / LOTO
B24: Other
B28: Risk Matrix Score (S×L)
B29: Likelihood 1-5 × Severity 1-5. Score >=15 Critical, >=10 High, >=5 Medium, else Low.

Sheet Admin
A1: 12 | SYSTEM ADMINISTRATION & TARGETS
A2: Yellow = editable settings. Used by Dashboard, Scorecard, VBA email and PDF export.
B4: PARAMETER | C4: VALUE | D4: NOTES
B5: Project Title | C5: KAZ PP Expansion Project | D5: Shown on reports
B6: Hours per worker per day (default) | C6: 10 | D6: Used if shift hours blank
B7: OSHA multiplier | C7: 1000000 | D7: Do not change (OSHA 200,000 optional)
B8: LTIFR Target | C8: 0 | D8: Project target
B9: TRIFR Target | C9: 1.5 | D9: Project target
B10: Observation close-out SLA (days) | C10: 7 | D10: Aging overdue after this
B11: Critical observation SLA (days) | C11: 1 | D11: 1 day — stored as 1
B12: Certificate warning (days) | C12: 30 | D12: Conditional formatting
B13: Certificate critical (days) | C13: 7 | D13: Red alert
B14: NCR close-out SLA (days) | C14: 14
B15: Scorecard: points per Open obs | C15: -2 | D15: Negative
B16: Scorecard: points per Overdue obs | C16: -5
B17: Scorecard: points per NCR | C17: -8
B18: Scorecard: points per LTI | C18: -25
B19: Scorecard: points per Recordable | C19: -15
B20: Scorecard: points per Near Miss (positive reporting) | C20: 1 | D20: Encourage reporting
B21: Scorecard starting points | C21: 100 | D21: Baseline
B22: Minimum score floor | C22: 0
B23: Outlook To (Project Management) | C23: pm@kaz-pp.example; ehs.manager@kaz-pp.example | D23: Semicolon separated
B24: Outlook CC (EHS) | C24: ehs.team@kaz-pp.example
B25: Send mail on Critical Incident | C25: YES | D25: YES/NO
B26: Send mail on new NCR | C26: YES | D26: YES/NO
B27: Weekly report folder path | C27: C:\EHS_Reports\KAZ_PP | D27: PDF export path
B28: OpenAI API Key (optional) | D28: Leave blank to use local CAPA engine
B29: OpenAI Model | C29: gpt-4o-mini | D29: If API used
B30: Admin password hint | C30: See Cover sheet I14 / C14 | D30: Never share
B31: Last LTI Date (override if needed) | D31: Leave blank to auto from Incidents
B32: Site location | C32: KAZ PP Site
B34: PROJECT EHS PERFORMANCE BANDS (used on Dashboard)
C35: From score | D35: Band
B36: Excellent | C36: 90 | D36: A — Excellent (Green)
B37: Satisfactory | C37: 75 | D37: B — Satisfactory
B38: Needs Improvement | C38: 60 | D38: C — Needs Improvement
B39: Unsatisfactory | C39: 0 | D39: D — Unsatisfactory / Stop Work review
B41: VBA BUTTONS (after importing .bas): Alt+F8 → EHS_SendCriticalAlert / EHS_ExportWeeklyPDF / EHS_ProtectAll / EHS_UnprotectAll / EHS_RefreshAging / EHS_FormatObservation

Sheet ManHours
A1: 02 | DAILY MAN-HOURS CALCULATOR
A2: Input daily headcount for Team Seisms and Team Al-Mayal. One consolidated total in cell P4 (and Dashboard).
B4: CONSOLIDATED PROJECT TOTAL MAN-HOURS | E4: Hours / worker default → | F4: =Admin!C6 | G4: ONE CELL — TOTAL MAN-HOURS (ALL DAYS, BOTH TEAMS) | J4: =I5 | L4: Seisms Σ | M4: =SUMIF(C8:C400,"Team Seisms",K8:K400)+SUMIF(C8:C400,"Shared / Indirect",K8:K400)/2 | N4: =I5
B5: Σ Seisms MH | C5: =SUM(G8:G400) | D5: Σ Al-Mayal MH | E5: =SUM(J8:J400) | F5: Σ Indirect | G5: =SUM(L8:L400) | H5: GRAND TOTAL (unified cell) | I5: =SUM(M8:M400) | L5: This I5 is the single consolidated man-hours output used by Dashboard KPIs.
B6: Yellow = input headcount. Blue = calculated man-hours. Copy formulas down as the project continues.
B7: Date | C7: Day | D7: Shift | E7: Seisms Headcount | F7: Seisms Hrs/person | G7: Seisms Man-Hours | H7: Al-Mayal Headcount | I7: Al-Mayal Hrs/person | J7: Al-Mayal Man-Hours | K7: Indirect / Visitors | L7: Indirect Hours | M7: DAILY TOTAL MH | N7: Remarks | O7: Entered by | P7: Weather / Notes
B8: 46082 | C8: =TEXT(B8,"DDD") | D8: Day | E8: 85 | F8: 10 | G8: =E8*F8 | H8: 70 | I8: 10 | J8: =H8*I8 | K8: 8 | L8: =K8*Admin!$C$6 | M8: =G8+J8+L8 | O8: EHS
B9: 46083 | C9: =TEXT(B9,"DDD") | D9: Day | E9: 88 | F9: 10 | G9: =E9*F9 | H9: 72 | I9: 10 | J9: =H9*I9 | K9: 8 | L9: =K9*Admin!$C$6 | M9: =G9+J9+L9 | O9: EHS
B10: 46084 | C10: =TEXT(B10,"DDD") | D10: Day | E10: 91 | F10: 10 | G10: =E10*F10 | H10: 74 | I10: 10 | J10: =H10*I10 | K10: 8 | L10: =K10*Admin!$C$6 | M10: =G10+J10+L10 | O10: EHS
B11: 46085 | C11: =TEXT(B11,"DDD") | D11: Day | E11: 94 | F11: 10 | G11: =E11*F11 | H11: 76 | I11: 10 | J11: =H11*I11 | K11: 8 | L11: =K11*Admin!$C$6 | M11: =G11+J11+L11 | O11: EHS
B12: 46086 | C12: =TEXT(B12,"DDD") | D12: Day | E12: 97 | F12: 10 | G12: =E12*F12 | H12: 70 | I12: 10 | J12: =H12*I12 | K12: 8 | L12: =K12*Admin!$C$6 | M12: =G12+J12+L12 | O12: EHS
B13: 46087 | C13: =TEXT(B13,"DDD") | D13: Day | E13: 85 | F13: 10 | G13: =E13*F13 | H13: 72 | I13: 10 | J13: =H13*I13 | K13: 8 | L13: =K13*Admin!$C$6 | M13: =G13+J13+L13 | O13: EHS
B14: 46088 | C14: =TEXT(B14,"DDD") | D14: Day | E14: 88 | F14: 10 | G14: =E14*F14 | H14: 74 | I14: 10 | J14: =H14*I14 | K14: 8 | L14: =K14*Admin!$C$6 | M14: =G14+J14+L14 | O14: EHS
B15: 46089 | C15: =TEXT(B15,"DDD") | D15: Day | E15: 91 | F15: 10 | G15: =E15*F15 | H15: 76 | I15: 10 | J15: =H15*I15 | K15: 8 | L15: =K15*Admin!$C$6 | M15: =G15+J15+L15 | O15: EHS
B16: 46090 | C16: =TEXT(B16,"DDD") | D16: Day | E16: 94 | F16: 10 | G16: =E16*F16 | H16: 70 | I16: 10 | J16: =H16*I16 | K16: 8 | L16: =K16*Admin!$C$6 | M16: =G16+J16+L16 | O16: EHS
B17: 46091 | C17: =TEXT(B17,"DDD") | D17: Day | E17: 97 | F17: 10 | G17: =E17*F17 | H17: 72 | I17: 10 | J17: =H17*I17 | K17: 8 | L17: =K17*Admin!$C$6 | M17: =G17+J17+L17 | O17: EHS
B18: 46092 | C18: =TEXT(B18,"DDD") | D18: Day | E18: 85 | F18: 10 | G18: =E18*F18 | H18: 74 | I18: 10 | J18: =H18*I18 | K18: 8 | L18: =K18*Admin!$C$6 | M18: =G18+J18+L18 | O18: EHS
B19: 46093 | C19: =TEXT(B19,"DDD") | D19: Day | E19: 88 | F19: 10 | G19: =E19*F19 | H19: 76 | I19: 10 | J19: =H19*I19 | K19: 8 | L19: =K19*Admin!$C$6 | M19: =G19+J19+L19 | O19: EHS
... B21: 46095 | C21: =TEXT(B21,"DDD") | D21: Day | E21: 94 | F21: 10 | G21: =E21*F21 | H21: 72 | I21: 10 | J21: =H21*I21 | K21: 8 | L21: =K21*Admin!$C$6 | M21: =G21+J21+L21 | O21: EHS
C22: =IF(B22="","",TEXT(B22,"DDD")) | G22: =IF(E22="","",E22*IF(F22="",Admin!$C$6,F22)) | J22: =IF(H22="","",H22*IF(I22="",Admin!$C$6,I22)) | L22: =IF(K22="","",K22*Admin!$C$6) | M22: =IF(AND(G22="",J22="",L22=""),"",N(G22)+N(J22)+N(L22))
C23: =IF(B23="","",TEXT(B23,"DDD")) | G23: =IF(E23="","",E23*IF(F23="",Admin!$C$6,F23)) | J23: =IF(H23="","",H23*IF(I23="",Admin!$C$6,I23)) | L23: =IF(K23="","",K23*Admin!$C$6) | M23: =IF(AND(G23="",J23="",L23=""),"",N(G23)+N(J23)+N(L23))
C24: =IF(B24="","",TEXT(B24,"DDD")) | G24: =IF(E24="","",E24*IF(F24="",Admin!$C$6,F24)) | J24: =IF(H24="","",H24*IF(I24="",Admin!$C$6,I24)) | L24: =IF(K24="","",K24*Admin!$C$6) | M24: =IF(AND(G24="",J24="",L24=""),"",N(G24)+N(J24)+N(L24))
C25: =IF(B25="","",TEXT(B25,"DDD")) | G25: =IF(E25="","",E25*IF(F25="",Admin!$C$6,F25)) | J25: =IF(H25="","",H25*IF(I25="",Admin!$C$6,I25)) | L25: =IF(K25="","",K25*Admin!$C$6) | M25: =IF(AND(G25="",J25="",L25=""),"",N(G25)+N(J25)+N(L25))
C26: =IF(B26="","",TEXT(B26,"DDD")) | G26: =IF(E26="","",E26*IF(F26="",Admin!$C$6,F26)) | J26: =IF(H26="","",H26*IF(I26="",Admin!$C$6,I26)) | L26: =IF(K26="","",K26*Admin!$C$6) | M26: =IF(AND(G26="",J26="",L26=""),"",N(G26)+N(J26)+N(L26))
C27: =IF(B27="","",TEXT(B27,"DDD")) | G27: =IF(E27="","",E27*IF(F27="",Admin!$C$6,F27)) | J27: =IF(H27="","",H27*IF(I27="",Admin!$C$6,I27)) | L27: =IF(K27="","",K27*Admin!$C$6) | M27: =IF(AND(G27="",J27="",L27=""),"",N(G27)+N(J27)+N(L27))
C28: =IF(B28="","",TEXT(B28,"DDD")) | G28: =IF(E28="","",E28*IF(F28="",Admin!$C$6,F28)) | J28: =IF(H28="","",H28*IF(I28="",Admin!$C$6,I28)) | L28: =IF(K28="","",K28*Admin!$C$6) | M28: =IF(AND(G28="",J28="",L28=""),"",N(G28)+N(J28)+N(L28))
C29: =IF(B29="","",TEXT(B29,"DDD")) | G29: =IF(E29="","",E29*IF(F29="",Admin!$C$6,F29)) | J29: =IF(H29="","",H29*IF(I29="",Admin!$C$6,I29)) | L29: =IF(K29="","",K29*Admin!$C$6) | M29: =IF(AND(G29="",J29="",L29=""),"",N(G29)+N(J29)+N(L29))
C30: =IF(B30="","",TEXT(B30,"DDD")) | G30: =IF(E30="","",E30*IF(F30="",Admin!$C$6,F30)) | J30: =IF(H30="","",H30*IF(I30="",Admin!$C$6,I30)) | L30: =IF(K30="","",K30*Admin!$C$6) | M30: =IF(AND(G30="",J30="",L30=""),"",N(G30)+N(J30)+N(L30))
C31: =IF(B31="","",TEXT(B31,"DDD")) | G31: =IF(E31="","",E31*IF(F31="",Admin!$C$6,F31)) | J31: =IF(H31="","",H31*IF(I31="",Admin!$C$6,I31)) | L31: =IF(K31="","",K31*Admin!$C$6) | M31: =IF(AND(G31="",J31="",L31=""),"",N(G31)+N(J31)+N(L31))
C32: =IF(B32="","",TEXT(B32,"DDD")) | G32: =IF(E32="","",E32*IF(F32="",Admin!$C$6,F32)) | J32: =IF(H32="","",H32*IF(I32="",Admin!$C$6,I32)) | L32: =IF(K32="","",K32*Admin!$C$6) | M32: =IF(AND(G32="",J32="",L32=""),"",N(G32)+N(J32)+N(L32))
C33: =IF(B33="","",TEXT(B33,"DDD")) | G33: =IF(E33="","",E33*IF(F33="",Admin!$C$6,F33)) | J33: =IF(H33="","",H33*IF(I33="",Admin!$C$6,I33)) | L33: =IF(K33="","",K33*Admin!$C$6) | M33: =IF(AND(G33="",J33="",L33=""),"",N(G33)+N(J33)+N(L33))
... C80: =IF(B80="","",TEXT(B80,"DDD")) | G80: =IF(E80="","",E80*IF(F80="",Admin!$C$6,F80)) | J80: =IF(H80="","",H80*IF(I80="",Admin!$C$6,I80)) | L80: =IF(K80="","",K80*Admin!$C$6) | M80: =IF(AND(G80="",J80="",L80=""),"",N(G80)+N(J80)+N(L80))

Sheet Incidents
A1: 03 | INCIDENT & CASE REGISTER (OSHA CLASSIFICATION)
A2: Record Near Miss, Unsafe Acts/Conditions, First Aid, Recordable, LTI. Feeds Dashboard counters and rates.
B3: KPI COUNTERS (auto) — Near Miss | Unsafe Act | Unsafe Condition | First Aid | Recordable | LTI | Open cases
B4: INC-ID | C4: Date | D4: Time | E4: Classification | F4: Location / Area | G4: Subcontractor | H4: PTW No. | I4: Injured / Involved | J4: Body Part | K4: Lost Days | L4: Recordable? (Y/N) | M4: LTI? (Y/N) | N4: Description | O4: Immediate Action | P4: Root Cause | Q4: Status | R4: Investigation Lead | S4: Closed Date | T4: Severity | V4: COUNTERS
B5: INC-001 | C5: 46083 | D5: 08:40 | E5: Near Miss | F5: Unit 2 Pipe Rack | G5: Team Seisms | H5: PTW-0142 | I5: N/A | K5: 0 | L5: =IF(E5="","",IF(OR(E5="Medical Treatment (MTC)",E5="Restricted Work (RWC)",E5="Lost Time Injury (LTI)",E5="Recordable Case",E5="Fatality"),"Y",IF(L5="Y","Y","N"))) | M5: =IF(E5="","",IF(OR(E5="Lost Time Injury (LTI)",E5="Fatality"),"Y","N")) | N5: Load swung within 2m of live line during tandem lift | O5: Stop work, re-plan lift | P5: Inadequate exclusion zone | Q5: Closed | R5: EHS Off. Ali | S5: 46084 | T5: High | V5: Near Miss | W5: =COUNTIF(E5:E200,"Near Miss")
B6: INC-002 | C6: 46086 | D6: 14:15 | E6: Unsafe Condition | F6: Excavation Grid C | G6: Team Al-Mayal | H6: PTW-0188 | I6: N/A | K6: 0 | L6: =IF(E6="","",IF(OR(E6="Medical Treatment (MTC)",E6="Restricted Work (RWC)",E6="Lost Time Injury (LTI)",E6="Recordable Case",E6="Fatality"),"Y",IF(L6="Y","Y","N"))) | M6: =IF(E6="","",IF(OR(E6="Lost Time Injury (LTI)",E6="Fatality"),"Y","N")) | N6: Excavation >1.2m without shoring / ladder | O6: Barrier + backfill temporary | P6: PTW controls not implemented | Q6: Closed | R6: EHS Off. Omar | S6: 46087 | T6: High | V6: Unsafe Act | W6: =COUNTIF(E5:E200,"Unsafe Act")
B7: INC-003 | C7: 46089 | D7: 11:05 | E7: First Aid | F7: Workshop | G7: Mechanical Subcontractor B | H7: PTW-0210 | I7: Worker #442 | J7: Hand | K7: 0 | L7: =IF(E7="","",IF(OR(E7="Medical Treatment (MTC)",E7="Restricted Work (RWC)",E7="Lost Time Injury (LTI)",E7="Recordable Case",E7="Fatality"),"Y",IF(L7="Y","Y","N"))) | M7: =IF(E7="","",IF(OR(E7="Lost Time Injury (LTI)",E7="Fatality"),"Y","N")) | N7: Minor cut while using utility knife without cut-resistant glove | O7: First aid, replace glove | P7: PPE gap | Q7: Closed | R7: Nurse | S7: 46089 | T7: Low | V7: Unsafe Condition | W7: =COUNTIF(E5:E200,"Unsafe Condition")
B8: INC-004 | C8: 46091 | D8: 16:20 | E8: Unsafe Act | F8: Scaffold Bay 4 | G8: Scaffolding Contractor D | H8: PTW-0225 | I8: N/A | K8: 0 | L8: =IF(E8="","",IF(OR(E8="Medical Treatment (MTC)",E8="Restricted Work (RWC)",E8="Lost Time Injury (LTI)",E8="Recordable Case",E8="Fatality"),"Y",IF(L8="Y","Y","N"))) | M8: =IF(E8="","",IF(OR(E8="Lost Time Injury (LTI)",E8="Fatality"),"Y","N")) | N8: Worker climbing scaffold without harness attached | O8: Stopped, TBT refresh | P8: Behavior / supervision | Q8: Open | R8: EHS Sup. Hassan | T8: Medium | V8: First Aid | W8: =COUNTIF(E5:E200,"First Aid")
B9: =IF(C9="","","INC-"&TEXT(r-4,"000")) | L9: =IF(E9="","",IF(OR(E9="Medical Treatment (MTC)",E9="Restricted Work (RWC)",E9="Lost Time Injury (LTI)",E9="Recordable Case",E9="Fatality"),"Y",IF(L9="Y","Y","N"))) | M9: =IF(E9="","",IF(OR(E9="Lost Time Injury (LTI)",E9="Fatality"),"Y","N")) | V9: Recordable | W9: =COUNTIF(L5:L200,"Y")
B10: =IF(C10="","","INC-"&TEXT(r-4,"000")) | L10: =IF(E10="","",IF(OR(E10="Medical Treatment (MTC)",E10="Restricted Work (RWC)",E10="Lost Time Injury (LTI)",E10="Recordable Case",E10="Fatality"),"Y",IF(L10="Y","Y","N"))) | M10: =IF(E10="","",IF(OR(E10="Lost Time Injury (LTI)",E10="Fatality"),"Y","N")) | V10: LTI | W10: =COUNTIF(M5:M200,"Y")
B11: =IF(C11="","","INC-"&TEXT(r-4,"000")) | L11: =IF(E11="","",IF(OR(E11="Medical Treatment (MTC)",E11="Restricted Work (RWC)",E11="Lost Time Injury (LTI)",E11="Recordable Case",E11="Fatality"),"Y",IF(L11="Y","Y","N"))) | M11: =IF(E11="","",IF(OR(E11="Lost Time Injury (LTI)",E11="Fatality"),"Y","N")) | V11: Fatalities | W11: =COUNTIF(E5:E200,"Fatality")
B12: =IF(C12="","","INC-"&TEXT(r-4,"000")) | L12: =IF(E12="","",IF(OR(E12="Medical Treatment (MTC)",E12="Restricted Work (RWC)",E12="Lost Time Injury (LTI)",E12="Recordable Case",E12="Fatality"),"Y",IF(L12="Y","Y","N"))) | M12: =IF(E12="","",IF(OR(E12="Lost Time Injury (LTI)",E12="Fatality"),"Y","N")) | V12: Open | W12: =COUNTIF(Q5:Q200,"Open")+COUNTIF(Q5:Q200,"In Progress")
B13: =IF(C13="","","INC-"&TEXT(r-4,"000")) | L13: =IF(E13="","",IF(OR(E13="Medical Treatment (MTC)",E13="Restricted Work (RWC)",E13="Lost Time Injury (LTI)",E13="Recordable Case",E13="Fatality"),"Y",IF(L13="Y","Y","N"))) | M13: =IF(E13="","",IF(OR(E13="Lost Time Injury (LTI)",E13="Fatality"),"Y","N")) | V13: Last LTI Date | W13: =IFERROR(AGGREGATE(14,6,C5:C200/(M5:M200="Y"),1),"None")
B14: =IF(C14="","","INC-"&TEXT(r-4,"000")) | L14: =IF(E14="","",IF(OR(E14="Medical Treatment (MTC)",E14="Restricted Work (RWC)",E14="Lost Time Injury (LTI)",E14="Recordable Case",E14="Fatality"),"Y",IF(L14="Y","Y","N"))) | M14: =IF(E14="","",IF(OR(E14="Lost Time Injury (LTI)",E14="Fatality"),"Y","N")) | V14: Lost days sum | W14: =SUM(K5:K200)
B15: =IF(C15="","","INC-"&TEXT(r-4,"000")) | L15: =IF(E15="","",IF(OR(E15="Medical Treatment (MTC)",E15="Restricted Work (RWC)",E15="Lost Time Injury (LTI)",E15="Recordable Case",E15="Fatality"),"Y",IF(L15="Y","Y","N"))) | M15: =IF(E15="","",IF(OR(E15="Lost Time Injury (LTI)",E15="Fatality"),"Y","N"))
B16: =IF(C16="","","INC-"&TEXT(r-4,"000")) | L16: =IF(E16="","",IF(OR(E16="Medical Treatment (MTC)",E16="Restricted Work (RWC)",E16="Lost Time Injury (LTI)",E16="Recordable Case",E16="Fatality"),"Y",IF(L16="Y","Y","N"))) | M16: =IF(E16="","",IF(OR(E16="Lost Time Injury (LTI)",E16="Fatality"),"Y","N"))
B17: =IF(C17="","","INC-"&TEXT(r-4,"000")) | L17: =IF(E17="","",IF(OR(E17="Medical Treatment (MTC)",E17="Restricted Work (RWC)",E17="Lost Time Injury (LTI)",E17="Recordable Case",E17="Fatality"),"Y",IF(L17="Y","Y","N"))) | M17: =IF(E17="","",IF(OR(E17="Lost Time Injury (LTI)",E17="Fatality"),"Y","N"))
B18: =IF(C18="","","INC-"&TEXT(r-4,"000")) | L18: =IF(E18="","",IF(OR(E18="Medical Treatment (MTC)",E18="Restricted Work (RWC)",E18="Lost Time Injury (LTI)",E18="Recordable Case",E18="Fatality"),"Y",IF(L18="Y","Y","N"))) | M18: =IF(E18="","",IF(OR(E18="Lost Time Injury (LTI)",E18="Fatality"),"Y","N"))
B19: =IF(C19="","","INC-"&TEXT(r-4,"000")) | L19: =IF(E19="","",IF(OR(E19="Medical Treatment (MTC)",E19="Restricted Work (RWC)",E19="Lost Time Injury (LTI)",E19="Recordable Case",E19="Fatality"),"Y",IF(L19="Y","Y","N"))) | M19: =IF(E19="","",IF(OR(E19="Lost Time Injury (LTI)",E19="Fatality"),"Y","N"))
B20: =IF(C20="","","INC-"&TEXT(r-4,"000")) | L20: =IF(E20="","",IF(OR(E20="Medical Treatment (MTC)",E20="Restricted Work (RWC)",E20="Lost Time Injury (LTI)",E20="Recordable Case",E20="Fatality"),"Y",IF(L20="Y","Y","N"))) | M20: =IF(E20="","",IF(OR(E20="Lost Time Injury (LTI)",E20="Fatality"),"Y","N"))
B21: =IF(C21="","","INC-"&TEXT(r-4,"000")) | L21: =IF(E21="","",IF(OR(E21="Medical Treatment (MTC)",E21="Restricted Work (RWC)",E21="Lost Time Injury (LTI)",E21="Recordable Case",E21="Fatality"),"Y",IF(L21="Y","Y","N"))) | M21: =IF(E21="","",IF(OR(E21="Lost Time Injury (LTI)",E21="Fatality"),"Y","N"))
B22: =IF(C22="","","INC-"&TEXT(r-4,"000")) | L22: =IF(E22="","",IF(OR(E22="Medical Treatment (MTC)",E22="Restricted Work (RWC)",E22="Lost Time Injury (LTI)",E22="Recordable Case",E22="Fatality"),"Y",IF(L22="Y","Y","N"))) | M22: =IF(E22="","",IF(OR(E22="Lost Time Injury (LTI)",E22="Fatality"),"Y","N"))
B23: =IF(C23="","","INC-"&TEXT(r-4,"000")) | L23: =IF(E23="","",IF(OR(E23="Medical Treatment (MTC)",E23="Restricted Work (RWC)",E23="Lost Time Injury (LTI)",E23="Recordable Case",E23="Fatality"),"Y",IF(L23="Y","Y","N"))) | M23: =IF(E23="","",IF(OR(E23="Lost Time Injury (LTI)",E23="Fatality"),"Y","N"))
B24: =IF(C24="","","INC-"&TEXT(r-4,"000")) | L24: =IF(E24="","",IF(OR(E24="Medical Treatment (MTC)",E24="Restricted Work (RWC)",E24="Lost Time Injury (LTI)",E24="Recordable Case",E24="Fatality"),"Y",IF(L24="Y","Y","N"))) | M24: =IF(E24="","",IF(OR(E24="Lost Time Injury (LTI)",E24="Fatality"),"Y","N"))
B25: =IF(C25="","","INC-"&TEXT(r-4,"000")) | L25: =IF(E25="","",IF(OR(E25="Medical Treatment (MTC)",E25="Restricted Work (RWC)",E25="Lost Time Injury (LTI)",E25="Recordable Case",E25="Fatality"),"Y",IF(L25="Y","Y","N"))) | M25: =IF(E25="","",IF(OR(E25="Lost Time Injury (LTI)",E25="Fatality"),"Y","N"))
B26: =IF(C26="","","INC-"&TEXT(r-4,"000")) | L26: =IF(E26="","",IF(OR(E26="Medical Treatment (MTC)",E26="Restricted Work (RWC)",E26="Lost Time Injury (LTI)",E26="Recordable Case",E26="Fatality"),"Y",IF(L26="Y","Y","N"))) | M26: =IF(E26="","",IF(OR(E26="Lost Time Injury (LTI)",E26="Fatality"),"Y","N"))
... B119: =IF(C119="","","INC-"&TEXT(r-4,"000")) | L119: =IF(E119="","",IF(OR(E119="Medical Treatment (MTC)",E119="Restricted Work (RWC)",E119="Lost Time Injury (LTI)",E119="Recordable Case",E119="Fatality"),"Y",IF(L119="Y","Y","N"))) | M119: =IF(E119="","",IF(OR(E119="Lost Time Injury (LTI)",E119="Fatality"),"Y","N"))

Sheet Observations
A1: 04 | OBSERVATION TRACKER & AGING SYSTEM
A2: Overdue Days escalate daily while status is Open / In Progress. Frequency Count = repeats of same type + area + contractor.
B4: OBS-ID | C4: Date | D4: Type | E4: Severity | F4: Status | G4: Subcontractor | H4: PTW Number | I4: Location / Area | J4: Observation (raw) | K4: Immediate Action | L4: Action Owner | M4: Target Close | N4: Closed Date | O4: Overdue Days | P4: Frequency Count | Q4: Repeat Flag | R4: Reported by | S4: NCR Linked | T4: Risk Score | V4: OBS KPIs
B5: OBS-001 | C5: 46082 | D5: Lifting Operations | E5: High | F5: Closed | G5: Lifting Contractor E | H5: PTW-0101 | I5: Laydown A | J5: Tag line not used on 12t load | K5: Stop lift, toolbox | L5: Lift Sup. | M5: 46083 | N5: 46083 | O5: =IF(C5="","",IF(OR(F5="Closed",F5=""),0,IF(N5<>"",MAX(0,N5-M5),MAX(0,TODAY()-IF(M5="",C5+IF(E5="Critical",Admin!$C$11,Admin!$C$10),M5))))) | P5: =IF(D5="","",COUNTIFS($D$5:$D$250,D5,$I$5:$I$250,I5,$G$5:$G$250,G5)) | Q5: =IF(P5="","",IF(P5>=3,"REPEAT ≥3",IF(P5=2,"REPEAT","Unique"))) | R5: Ahmed | T5: =IF(E5="","",IF(E5="Critical",25,IF(E5="High",16,IF(E5="Medium",9,4)))) | V5: Total | W5: =COUNTA(C5:C250)
B6: OBS-002 | C6: 46084 | D6: Working at Height | E6: Critical | F6: Open | G6: Team Seisms | H6: PTW-0155 | I6: Boiler roof | J6: Unprotected edge 8m, no harness anchorage | K6: Barrier 2m, stop work | L6: Site Eng. | M6: 46085 | O6: =IF(C6="","",IF(OR(F6="Closed",F6=""),0,IF(N6<>"",MAX(0,N6-M6),MAX(0,TODAY()-IF(M6="",C6+IF(E6="Critical",Admin!$C$11,Admin!$C$10),M6))))) | P6: =IF(D6="","",COUNTIFS($D$5:$D$250,D6,$I$5:$I$250,I6,$G$5:$G$250,G6)) | Q6: =IF(P6="","",IF(P6>=3,"REPEAT ≥3",IF(P6=2,"REPEAT","Unique"))) | R6: Sara | T6: =IF(E6="","",IF(E6="Critical",25,IF(E6="High",16,IF(E6="Medium",9,4)))) | V6: Open | W6: =COUNTIF(F5:F250,"Open")
B7: OBS-003 | C7: 46085 | D7: Excavation | E7: High | F7: In Progress | G7: Team Al-Mayal | H7: PTW-0160 | I7: Grid B-4 | J7: Spoil stored at edge of 2.1m trench | K7: Move spoil 1m, shore | L7: Civil Sup. | M7: 46087 | O7: =IF(C7="","",IF(OR(F7="Closed",F7=""),0,IF(N7<>"",MAX(0,N7-M7),MAX(0,TODAY()-IF(M7="",C7+IF(E7="Critical",Admin!$C$11,Admin!$C$10),M7))))) | P7: =IF(D7="","",COUNTIFS($D$5:$D$250,D7,$I$5:$I$250,I7,$G$5:$G$250,G7)) | Q7: =IF(P7="","",IF(P7>=3,"REPEAT ≥3",IF(P7=2,"REPEAT","Unique"))) | R7: Omar | T7: =IF(E7="","",IF(E7="Critical",25,IF(E7="High",16,IF(E7="Medium",9,4)))) | V7: In Progress | W7: =COUNTIF(F5:F250,"In Progress")
B8: OBS-004 | C8: 46087 | D8: Work Permits / PTW | E8: Medium | F8: Open | G8: Electrical Subcontractor C | H8: PTW-0172 | I8: Substation | J8: PTW expired, work continuing | K8: Stop, reissue PTW | L8: EA | M8: 46088 | O8: =IF(C8="","",IF(OR(F8="Closed",F8=""),0,IF(N8<>"",MAX(0,N8-M8),MAX(0,TODAY()-IF(M8="",C8+IF(E8="Critical",Admin!$C$11,Admin!$C$10),M8))))) | P8: =IF(D8="","",COUNTIFS($D$5:$D$250,D8,$I$5:$I$250,I8,$G$5:$G$250,G8)) | Q8: =IF(P8="","",IF(P8>=3,"REPEAT ≥3",IF(P8=2,"REPEAT","Unique"))) | R8: Hassan | T8: =IF(E8="","",IF(E8="Critical",25,IF(E8="High",16,IF(E8="Medium",9,4)))) | V8: Closed | W8: =COUNTIF(F5:F250,"Closed")
B9: OBS-005 | C9: 46088 | D9: Scaffolding | E9: High | F9: Open | G9: Scaffolding Contractor D | H9: PTW-0180 | I9: Pipe rack 3 | J9: Incomplete scaffold — no toe boards, green tag on red | K9: Red tag, dismantle | L9: Scaffold I | M9: 46089 | O9: =IF(C9="","",IF(OR(F9="Closed",F9=""),0,IF(N9<>"",MAX(0,N9-M9),MAX(0,TODAY()-IF(M9="",C9+IF(E9="Critical",Admin!$C$11,Admin!$C$10),M9))))) | P9: =IF(D9="","",COUNTIFS($D$5:$D$250,D9,$I$5:$I$250,I9,$G$5:$G$250,G9)) | Q9: =IF(P9="","",IF(P9>=3,"REPEAT ≥3",IF(P9=2,"REPEAT","Unique"))) | R9: Ali | T9: =IF(E9="","",IF(E9="Critical",25,IF(E9="High",16,IF(E9="Medium",9,4)))) | V9: Overdue (days>0) | W9: =COUNTIF(O5:O250,">0")
B10: OBS-006 | C10: 46089 | D10: Lifting Operations | E10: Medium | F10: Closed | G10: Lifting Contractor E | H10: PTW-0184 | I10: Laydown A | J10: Out of date color code on sling | K10: Quarantine sling | L10: Store | M10: 46090 | N10: 46090 | O10: =IF(C10="","",IF(OR(F10="Closed",F10=""),0,IF(N10<>"",MAX(0,N10-M10),MAX(0,TODAY()-IF(M10="",C10+IF(E10="Critical",Admin!$C$11,Admin!$C$10),M10))))) | P10: =IF(D10="","",COUNTIFS($D$5:$D$250,D10,$I$5:$I$250,I10,$G$5:$G$250,G10)) | Q10: =IF(P10="","",IF(P10>=3,"REPEAT ≥3",IF(P10=2,"REPEAT","Unique"))) | R10: Ahmed | T10: =IF(E10="","",IF(E10="Critical",25,IF(E10="High",16,IF(E10="Medium",9,4)))) | V10: Critical open | W10: =COUNTIFS(E5:E250,"Critical",F5:F250,"<>Closed")
B11: OBS-007 | C11: 46090 | D11: Electrical | E11: High | F11: In Progress | G11: Electrical Subcontractor C | H11: PTW-0190 | I11: MCC room | J11: Panel open, no electrical barrier, live | K11: Isolate, LOTO | L11: Elec Sup. | M11: 46091 | O11: =IF(C11="","",IF(OR(F11="Closed",F11=""),0,IF(N11<>"",MAX(0,N11-M11),MAX(0,TODAY()-IF(M11="",C11+IF(E11="Critical",Admin!$C$11,Admin!$C$10),M11))))) | P11: =IF(D11="","",COUNTIFS($D$5:$D$250,D11,$I$5:$I$250,I11,$G$5:$G$250,G11)) | Q11: =IF(P11="","",IF(P11>=3,"REPEAT ≥3",IF(P11=2,"REPEAT","Unique"))) | R11: Nour | T11: =IF(E11="","",IF(E11="Critical",25,IF(E11="High",16,IF(E11="Medium",9,4))))
B12: OBS-008 | C12: 46091 | D12: Confined Space | E12: Critical | F12: Open | G12: Mechanical Subcontractor B | H12: PTW-0199 | I12: Tank T-12 | J12: Entry without gas test / attendant | K12: Evacuate, CS procedure | L12: EHS Mgr | M12: 46091 | O12: =IF(C12="","",IF(OR(F12="Closed",F12=""),0,IF(N12<>"",MAX(0,N12-M12),MAX(0,TODAY()-IF(M12="",C12+IF(E12="Critical",Admin!$C$11,Admin!$C$10),M12))))) | P12: =IF(D12="","",COUNTIFS($D$5:$D$250,D12,$I$5:$I$250,I12,$G$5:$G$250,G12)) | Q12: =IF(P12="","",IF(P12>=3,"REPEAT ≥3",IF(P12=2,"REPEAT","Unique"))) | R12: Sara | T12: =IF(E12="","",IF(E12="Critical",25,IF(E12="High",16,IF(E12="Medium",9,4))))
O13: =IF(C13="","",IF(OR(F13="Closed",F13=""),0,IF(N13<>"",MAX(0,N13-M13),MAX(0,TODAY()-IF(M13="",C13+IF(E13="Critical",Admin!$C$11,Admin!$C$10),M13))))) | P13: =IF(D13="","",COUNTIFS($D$5:$D$250,D13,$I$5:$I$250,I13,$G$5:$G$250,G13)) | Q13: =IF(P13="","",IF(P13>=3,"REPEAT ≥3",IF(P13=2,"REPEAT","Unique"))) | T13: =IF(E13="","",IF(E13="Critical",25,IF(E13="High",16,IF(E13="Medium",9,4))))
O14: =IF(C14="","",IF(OR(F14="Closed",F14=""),0,IF(N14<>"",MAX(0,N14-M14),MAX(0,TODAY()-IF(M14="",C14+IF(E14="Critical",Admin!$C$11,Admin!$C$10),M14))))) | P14: =IF(D14="","",COUNTIFS($D$5:$D$250,D14,$I$5:$I$250,I14,$G$5:$G$250,G14)) | Q14: =IF(P14="","",IF(P14>=3,"REPEAT ≥3",IF(P14=2,"REPEAT","Unique"))) | T14: =IF(E14="","",IF(E14="Critical",25,IF(E14="High",16,IF(E14="Medium",9,4))))
O15: =IF(C15="","",IF(OR(F15="Closed",F15=""),0,IF(N15<>"",MAX(0,N15-M15),MAX(0,TODAY()-IF(M15="",C15+IF(E15="Critical",Admin!$C$11,Admin!$C$10),M15))))) | P15: =IF(D15="","",COUNTIFS($D$5:$D$250,D15,$I$5:$I$250,I15,$G$5:$G$250,G15)) | Q15: =IF(P15="","",IF(P15>=3,"REPEAT ≥3",IF(P15=2,"REPEAT","Unique"))) | T15: =IF(E15="","",IF(E15="Critical",25,IF(E15="High",16,IF(E15="Medium",9,4))))
O16: =IF(C16="","",IF(OR(F16="Closed",F16=""),0,IF(N16<>"",MAX(0,N16-M16),MAX(0,TODAY()-IF(M16="",C16+IF(E16="Critical",Admin!$C$11,Admin!$C$10),M16))))) | P16: =IF(D16="","",COUNTIFS($D$5:$D$250,D16,$I$5:$I$250,I16,$G$5:$G$250,G16)) | Q16: =IF(P16="","",IF(P16>=3,"REPEAT ≥3",IF(P16=2,"REPEAT","Unique"))) | T16: =IF(E16="","",IF(E16="Critical",25,IF(E16="High",16,IF(E16="Medium",9,4))))
O17: =IF(C17="","",IF(OR(F17="Closed",F17=""),0,IF(N17<>"",MAX(0,N17-M17),MAX(0,TODAY()-IF(M17="",C17+IF(E17="Critical",Admin!$C$11,Admin!$C$10),M17))))) | P17: =IF(D17="","",COUNTIFS($D$5:$D$250,D17,$I$5:$I$250,I17,$G$5:$G$250,G17)) | Q17: =IF(P17="","",IF(P17>=3,"REPEAT ≥3",IF(P17=2,"REPEAT","Unique"))) | T17: =IF(E17="","",IF(E17="Critical",25,IF(E17="High",16,IF(E17="Medium",9,4))))
O18: =IF(C18="","",IF(OR(F18="Closed",F18=""),0,IF(N18<>"",MAX(0,N18-M18),MAX(0,TODAY()-IF(M18="",C18+IF(E18="Critical",Admin!$C$11,Admin!$C$10),M18))))) | P18: =IF(D18="","",COUNTIFS($D$5:$D$250,D18,$I$5:$I$250,I18,$G$5:$G$250,G18)) | Q18: =IF(P18="","",IF(P18>=3,"REPEAT ≥3",IF(P18=2,"REPEAT","Unique"))) | T18: =IF(E18="","",IF(E18="Critical",25,IF(E18="High",16,IF(E18="Medium",9,4))))
O19: =IF(C19="","",IF(OR(F19="Closed",F19=""),0,IF(N19<>"",MAX(0,N19-M19),MAX(0,TODAY()-IF(M19="",C19+IF(E19="Critical",Admin!$C$11,Admin!$C$10),M19))))) | P19: =IF(D19="","",COUNTIFS($D$5:$D$250,D19,$I$5:$I$250,I19,$G$5:$G$250,G19)) | Q19: =IF(P19="","",IF(P19>=3,"REPEAT ≥3",IF(P19=2,"REPEAT","Unique"))) | T19: =IF(E19="","",IF(E19="Critical",25,IF(E19="High",16,IF(E19="Medium",9,4))))
O20: =IF(C20="","",IF(OR(F20="Closed",F20=""),0,IF(N20<>"",MAX(0,N20-M20),MAX(0,TODAY()-IF(M20="",C20+IF(E20="Critical",Admin!$C$11,Admin!$C$10),M20))))) | P20: =IF(D20="","",COUNTIFS($D$5:$D$250,D20,$I$5:$I$250,I20,$G$5:$G$250,G20)) | Q20: =IF(P20="","",IF(P20>=3,"REPEAT ≥3",IF(P20=2,"REPEAT","Unique"))) | T20: =IF(E20="","",IF(E20="Critical",25,IF(E20="High",16,IF(E20="Medium",9,4))))
O21: =IF(C21="","",IF(OR(F21="Closed",F21=""),0,IF(N21<>"",MAX(0,N21-M21),MAX(0,TODAY()-IF(M21="",C21+IF(E21="Critical",Admin!$C$11,Admin!$C$10),M21))))) | P21: =IF(D21="","",COUNTIFS($D$5:$D$250,D21,$I$5:$I$250,I21,$G$5:$G$250,G21)) | Q21: =IF(P21="","",IF(P21>=3,"REPEAT ≥3",IF(P21=2,"REPEAT","Unique"))) | T21: =IF(E21="","",IF(E21="Critical",25,IF(E21="High",16,IF(E21="Medium",9,4))))
O22: =IF(C22="","",IF(OR(F22="Closed",F22=""),0,IF(N22<>"",MAX(0,N22-M22),MAX(0,TODAY()-IF(M22="",C22+IF(E22="Critical",Admin!$C$11,Admin!$C$10),M22))))) | P22: =IF(D22="","",COUNTIFS($D$5:$D$250,D22,$I$5:$I$250,I22,$G$5:$G$250,G22)) | Q22: =IF(P22="","",IF(P22>=3,"REPEAT ≥3",IF(P22=2,"REPEAT","Unique"))) | T22: =IF(E22="","",IF(E22="Critical",25,IF(E22="High",16,IF(E22="Medium",9,4))))
O23: =IF(C23="","",IF(OR(F23="Closed",F23=""),0,IF(N23<>"",MAX(0,N23-M23),MAX(0,TODAY()-IF(M23="",C23+IF(E23="Critical",Admin!$C$11,Admin!$C$10),M23))))) | P23: =IF(D23="","",COUNTIFS($D$5:$D$250,D23,$I$5:$I$250,I23,$G$5:$G$250,G23)) | Q23: =IF(P23="","",IF(P23>=3,"REPEAT ≥3",IF(P23=2,"REPEAT","Unique"))) | T23: =IF(E23="","",IF(E23="Critical",25,IF(E23="High",16,IF(E23="Medium",9,4))))
O24: =IF(C24="","",IF(OR(F24="Closed",F24=""),0,IF(N24<>"",MAX(0,N24-M24),MAX(0,TODAY()-IF(M24="",C24+IF(E24="Critical",Admin!$C$11,Admin!$C$10),M24))))) | P24: =IF(D24="","",COUNTIFS($D$5:$D$250,D24,$I$5:$I$250,I24,$G$5:$G$250,G24)) | Q24: =IF(P24="","",IF(P24>=3,"REPEAT ≥3",IF(P24=2,"REPEAT","Unique"))) | T24: =IF(E24="","",IF(E24="Critical",25,IF(E24="High",16,IF(E24="Medium",9,4))))
... O249: =IF(C249="","",IF(OR(F249="Closed",F249=""),0,IF(N249<>"",MAX(0,N249-M249),MAX(0,TODAY()-IF(M249="",C249+IF(E249="Critical",Admin!$C$11,Admin!$C$10),M249))))) | P249: =IF(D249="","",COUNTIFS($D$5:$D$250,D249,$I$5:$I$250,I249,$G$5:$G$250,G249)) | Q249: =IF(P249="","",IF(P249>=3,"REPEAT ≥3",IF(P249=2,"REPEAT","Unique"))) | T249: =IF(E249="","",IF(E249="Critical",25,IF(E249="High",16,IF(E249="Medium",9,4))))

Sheet NCR
A1: 05 | NON-CONFORMANCE REPORTS (NCR)
A2: New NCR can trigger Outlook email via VBA (EHS_SendNCRAlert). Links to subcontractors scorecard.
B4: NCR-ID | C4: Date | D4: Subcontractor | E4: Source (OBS/INC) | F4: Finding | G4: Required Action | H4: Owner | I4: Priority | J4: Target Date | K4: Closed Date | L4: Status | M4: Days Open | N4: Issued by | O4: Related PTW | Q4: Open NCRs | R4: =COUNTIF(L5:L80,"Open")+COUNTIF(L5:L80,"In Progress")
B5: NCR-001 | C5: 46085 | D5: Team Seisms | E5: OBS-002 | F5: Unprotected edge WAH — systemic PTW failure | G5: Revise WAH permit checklist; retrain crew; barrier standard | H5: Construction Mgr | I5: Critical | J5: 46092 | L5: Open | M5: =IF(C5="","",IF(L5="Closed",IF(K5="",0,K5-C5),TODAY()-C5)) | N5: EHS Manager | O5: PTW-0155
B6: NCR-002 | C6: 46091 | D6: Mechanical Subcontractor B | E6: OBS-008 | F6: Confined space entry without atmospheric test | G6: Stop CS work; full CS procedure rollout; competency cards | H6: Mech PM | I6: Critical | J6: 46098 | L6: Open | M6: =IF(C6="","",IF(L6="Closed",IF(K6="",0,K6-C6),TODAY()-C6)) | N6: EHS Manager | O6: PTW-0199
M7: =IF(C7="","",IF(L7="Closed",IF(K7="",0,K7-C7),TODAY()-C7))
M8: =IF(C8="","",IF(L8="Closed",IF(K8="",0,K8-C8),TODAY()-C8))
M9: =IF(C9="","",IF(L9="Closed",IF(K9="",0,K9-C9),TODAY()-C9))
M10: =IF(C10="","",IF(L10="Closed",IF(K10="",0,K10-C10),TODAY()-C10))
M11: =IF(C11="","",IF(L11="Closed",IF(K11="",0,K11-C11),TODAY()-C11))
M12: =IF(C12="","",IF(L12="Closed",IF(K12="",0,K12-C12),TODAY()-C12))
M13: =IF(C13="","",IF(L13="Closed",IF(K13="",0,K13-C13),TODAY()-C13))
M14: =IF(C14="","",IF(L14="Closed",IF(K14="",0,K14-C14),TODAY()-C14))
M15: =IF(C15="","",IF(L15="Closed",IF(K15="",0,K15-C15),TODAY()-C15))
M16: =IF(C16="","",IF(L16="Closed",IF(K16="",0,K16-C16),TODAY()-C16))
M17: =IF(C17="","",IF(L17="Closed",IF(K17="",0,K17-C17),TODAY()-C17))
M18: =IF(C18="","",IF(L18="Closed",IF(K18="",0,K18-C18),TODAY()-C18))
... M79: =IF(C79="","",IF(L79="Closed",IF(K79="",0,K79-C79),TODAY()-C79))

Sheet Scorecard
A1: 06 | SUBCONTRACTOR EHS SCORECARD
A2: Automatic scoring from Observations, Incidents and NCRs. Baseline 100. Floor = Admin minimum.
B4: Subcontractor | C4: Open OBS | D4: Overdue OBS | E4: Total OBS | F4: NCRs | G4: LTI | H4: Recordable | I4: Near Miss | J4: First Aid | K4: Raw Penalty/Bonus | L4: SCORE /100 | M4: Band | N4: Trend / Comment
B5: =Lookups!E5 | C5: =COUNTIFS(Observations!$G$5:$G$250,B5,Observations!$F$5:$F$250,"Open")+COUNTIFS(Observations!$G$5:$G$250,B5,Observations!$F$5:$F$250,"In Progress") | D5: =COUNTIFS(Observations!$G$5:$G$250,B5,Observations!$O$5:$O$250,">0") | E5: =COUNTIF(Observations!$G$5:$G$250,B5) | F5: =COUNTIF(NCR!$D$5:$D$80,B5) | G5: =COUNTIFS(Incidents!$G$5:$G$200,B5,Incidents!$M$5:$M$200,"Y") | H5: =COUNTIFS(Incidents!$G$5:$G$200,B5,Incidents!$L$5:$L$200,"Y") | I5: =COUNTIFS(Incidents!$G$5:$G$200,B5,Incidents!$E$5:$E$200,"Near Miss") | J5: =COUNTIFS(Incidents!$G$5:$G$200,B5,Incidents!$E$5:$E$200,"First Aid") | K5: =C5*Admin!$C$15+D5*Admin!$C$16+F5*Admin!$C$17+G5*Admin!$C$18+H5*Admin!$C$19+I5*Admin!$C$20 | L5: =MAX(Admin!$C$22,Admin!$C$21+K5) | M5: =IF(L5>=Admin!$C$36,"A — Excellent",IF(L5>=Admin!$C$37,"B — Satisfactory",IF(L5>=Admin!$C$38,"C — Needs Improvement","D — Unsatisfactory")))
B6: =Lookups!E6 | C6: =COUNTIFS(Observations!$G$5:$G$250,B6,Observations!$F$5:$F$250,"Open")+COUNTIFS(Observations!$G$5:$G$250,B6,Observations!$F$5:$F$250,"In Progress") | D6: =COUNTIFS(Observations!$G$5:$G$250,B6,Observations!$O$5:$O$250,">0") | E6: =COUNTIF(Observations!$G$5:$G$250,B6) | F6: =COUNTIF(NCR!$D$5:$D$80,B6) | G6: =COUNTIFS(Incidents!$G$5:$G$200,B6,Incidents!$M$5:$M$200,"Y") | H6: =COUNTIFS(Incidents!$G$5:$G$200,B6,Incidents!$L$5:$L$200,"Y") | I6: =COUNTIFS(Incidents!$G$5:$G$200,B6,Incidents!$E$5:$E$200,"Near Miss") | J6: =COUNTIFS(Incidents!$G$5:$G$200,B6,Incidents!$E$5:$E$200,"First Aid") | K6: =C6*Admin!$C$15+D6*Admin!$C$16+F6*Admin!$C$17+G6*Admin!$C$18+H6*Admin!$C$19+I6*Admin!$C$20 | L6: =MAX(Admin!$C$22,Admin!$C$21+K6) | M6: =IF(L6>=Admin!$C$36,"A — Excellent",IF(L6>=Admin!$C$37,"B — Satisfactory",IF(L6>=Admin!$C$38,"C — Needs Improvement","D — Unsatisfactory")))
B7: =Lookups!E7 | C7: =COUNTIFS(Observations!$G$5:$G$250,B7,Observations!$F$5:$F$250,"Open")+COUNTIFS(Observations!$G$5:$G$250,B7,Observations!$F$5:$F$250,"In Progress") | D7: =COUNTIFS(Observations!$G$5:$G$250,B7,Observations!$O$5:$O$250,">0") | E7: =COUNTIF(Observations!$G$5:$G$250,B7) | F7: =COUNTIF(NCR!$D$5:$D$80,B7) | G7: =COUNTIFS(Incidents!$G$5:$G$200,B7,Incidents!$M$5:$M$200,"Y") | H7: =COUNTIFS(Incidents!$G$5:$G$200,B7,Incidents!$L$5:$L$200,"Y") | I7: =COUNTIFS(Incidents!$G$5:$G$200,B7,Incidents!$E$5:$E$200,"Near Miss") | J7: =COUNTIFS(Incidents!$G$5:$G$200,B7,Incidents!$E$5:$E$200,"First Aid") | K7: =C7*Admin!$C$15+D7*Admin!$C$16+F7*Admin!$C$17+G7*Admin!$C$18+H7*Admin!$C$19+I7*Admin!$C$20 | L7: =MAX(Admin!$C$22,Admin!$C$21+K7) | M7: =IF(L7>=Admin!$C$36,"A — Excellent",IF(L7>=Admin!$C$37,"B — Satisfactory",IF(L7>=Admin!$C$38,"C — Needs Improvement","D — Unsatisfactory")))
B8: =Lookups!E8 | C8: =COUNTIFS(Observations!$G$5:$G$250,B8,Observations!$F$5:$F$250,"Open")+COUNTIFS(Observations!$G$5:$G$250,B8,Observations!$F$5:$F$250,"In Progress") | D8: =COUNTIFS(Observations!$G$5:$G$250,B8,Observations!$O$5:$O$250,">0") | E8: =COUNTIF(Observations!$G$5:$G$250,B8) | F8: =COUNTIF(NCR!$D$5:$D$80,B8) | G8: =COUNTIFS(Incidents!$G$5:$G$200,B8,Incidents!$M$5:$M$200,"Y") | H8: =COUNTIFS(Incidents!$G$5:$G$200,B8,Incidents!$L$5:$L$200,"Y") | I8: =COUNTIFS(Incidents!$G$5:$G$200,B8,Incidents!$E$5:$E$200,"Near Miss") | J8: =COUNTIFS(Incidents!$G$5:$G$200,B8,Incidents!$E$5:$E$200,"First Aid") | K8: =C8*Admin!$C$15+D8*Admin!$C$16+F8*Admin!$C$17+G8*Admin!$C$18+H8*Admin!$C$19+I8*Admin!$C$20 | L8: =MAX(Admin!$C$22,Admin!$C$21+K8) | M8: =IF(L8>=Admin!$C$36,"A — Excellent",IF(L8>=Admin!$C$37,"B — Satisfactory",IF(L8>=Admin!$C$38,"C — Needs Improvement","D — Unsatisfactory")))
B9: =Lookups!E9 | C9: =COUNTIFS(Observations!$G$5:$G$250,B9,Observations!$F$5:$F$250,"Open")+COUNTIFS(Observations!$G$5:$G$250,B9,Observations!$F$5:$F$250,"In Progress") | D9: =COUNTIFS(Observations!$G$5:$G$250,B9,Observations!$O$5:$O$250,">0") | E9: =COUNTIF(Observations!$G$5:$G$250,B9) | F9: =COUNTIF(NCR!$D$5:$D$80,B9) | G9: =COUNTIFS(Incidents!$G$5:$G$200,B9,Incidents!$M$5:$M$200,"Y") | H9: =COUNTIFS(Incidents!$G$5:$G$200,B9,Incidents!$L$5:$L$200,"Y") | I9: =COUNTIFS(Incidents!$G$5:$G$200,B9,Incidents!$E$5:$E$200,"Near Miss") | J9: =COUNTIFS(Incidents!$G$5:$G$200,B9,Incidents!$E$5:$E$200,"First Aid") | K9: =C9*Admin!$C$15+D9*Admin!$C$16+F9*Admin!$C$17+G9*Admin!$C$18+H9*Admin!$C$19+I9*Admin!$C$20 | L9: =MAX(Admin!$C$22,Admin!$C$21+K9) | M9: =IF(L9>=Admin!$C$36,"A — Excellent",IF(L9>=Admin!$C$37,"B — Satisfactory",IF(L9>=Admin!$C$38,"C — Needs Improvement","D — Unsatisfactory")))
B10: =Lookups!E10 | C10: =COUNTIFS(Observations!$G$5:$G$250,B10,Observations!$F$5:$F$250,"Open")+COUNTIFS(Observations!$G$5:$G$250,B10,Observations!$F$5:$F$250,"In Progress") | D10: =COUNTIFS(Observations!$G$5:$G$250,B10,Observations!$O$5:$O$250,">0") | E10: =COUNTIF(Observations!$G$5:$G$250,B10) | F10: =COUNTIF(NCR!$D$5:$D$80,B10) | G10: =COUNTIFS(Incidents!$G$5:$G$200,B10,Incidents!$M$5:$M$200,"Y") | H10: =COUNTIFS(Incidents!$G$5:$G$200,B10,Incidents!$L$5:$L$200,"Y") | I10: =COUNTIFS(Incidents!$G$5:$G$200,B10,Incidents!$E$5:$E$200,"Near Miss") | J10: =COUNTIFS(Incidents!$G$5:$G$200,B10,Incidents!$E$5:$E$200,"First Aid") | K10: =C10*Admin!$C$15+D10*Admin!$C$16+F10*Admin!$C$17+G10*Admin!$C$18+H10*Admin!$C$19+I10*Admin!$C$20 | L10: =MAX(Admin!$C$22,Admin!$C$21+K10) | M10: =IF(L10>=Admin!$C$36,"A — Excellent",IF(L10>=Admin!$C$37,"B — Satisfactory",IF(L10>=Admin!$C$38,"C — Needs Improvement","D — Unsatisfactory")))
B11: =Lookups!E11 | C11: =COUNTIFS(Observations!$G$5:$G$250,B11,Observations!$F$5:$F$250,"Open")+COUNTIFS(Observations!$G$5:$G$250,B11,Observations!$F$5:$F$250,"In Progress") | D11: =COUNTIFS(Observations!$G$5:$G$250,B11,Observations!$O$5:$O$250,">0") | E11: =COUNTIF(Observations!$G$5:$G$250,B11) | F11: =COUNTIF(NCR!$D$5:$D$80,B11) | G11: =COUNTIFS(Incidents!$G$5:$G$200,B11,Incidents!$M$5:$M$200,"Y") | H11: =COUNTIFS(Incidents!$G$5:$G$200,B11,Incidents!$L$5:$L$200,"Y") | I11: =COUNTIFS(Incidents!$G$5:$G$200,B11,Incidents!$E$5:$E$200,"Near Miss") | J11: =COUNTIFS(Incidents!$G$5:$G$200,B11,Incidents!$E$5:$E$200,"First Aid") | K11: =C11*Admin!$C$15+D11*Admin!$C$16+F11*Admin!$C$17+G11*Admin!$C$18+H11*Admin!$C$19+I11*Admin!$C$20 | L11: =MAX(Admin!$C$22,Admin!$C$21+K11) | M11: =IF(L11>=Admin!$C$36,"A — Excellent",IF(L11>=Admin!$C$37,"B — Satisfactory",IF(L11>=Admin!$C$38,"C — Needs Improvement","D — Unsatisfactory")))
B12: =Lookups!E12 | C12: =COUNTIFS(Observations!$G$5:$G$250,B12,Observations!$F$5:$F$250,"Open")+COUNTIFS(Observations!$G$5:$G$250,B12,Observations!$F$5:$F$250,"In Progress") | D12: =COUNTIFS(Observations!$G$5:$G$250,B12,Observations!$O$5:$O$250,">0") | E12: =COUNTIF(Observations!$G$5:$G$250,B12) | F12: =COUNTIF(NCR!$D$5:$D$80,B12) | G12: =COUNTIFS(Incidents!$G$5:$G$200,B12,Incidents!$M$5:$M$200,"Y") | H12: =COUNTIFS(Incidents!$G$5:$G$200,B12,Incidents!$L$5:$L$200,"Y") | I12: =COUNTIFS(Incidents!$G$5:$G$200,B12,Incidents!$E$5:$E$200,"Near Miss") | J12: =COUNTIFS(Incidents!$G$5:$G$200,B12,Incidents!$E$5:$E$200,"First Aid") | K12: =C12*Admin!$C$15+D12*Admin!$C$16+F12*Admin!$C$17+G12*Admin!$C$18+H12*Admin!$C$19+I12*Admin!$C$20 | L12: =MAX(Admin!$C$22,Admin!$C$21+K12) | M12: =IF(L12>=Admin!$C$36,"A — Excellent",IF(L12>=Admin!$C$37,"B — Satisfactory",IF(L12>=Admin!$C$38,"C — Needs Improvement","D — Unsatisfactory")))
B32: Scoring model: Start at Admin!C21 (default 100). Open OBS, Overdue, NCR, LTI, Recordable subtract points. Near Miss reporting adds points (positive reporting culture).

Sheet CAPA_AI
A1: 07 | AI CORRECTIVE ACTION & CONVERSION HUB
A2: Paste raw notes in column C. VBA EHS_FormatObservation converts to official EHS wording + CAPA. Optional OpenAI API in Admin!C28.
B4: HOW TO USE
B5: 1) Enter RAW note in C (yellow). 2) Select the row and run macro EHS_FormatObservation (or click after importing VBA). 3) Column D receives official bilingual-style EHS observation. Column E receives CAPA (Corrective & Preventive). 4) If Admin API key is blank, a built-in rule engine (keywords: lift, scaffold, excav, confined, electrical, PTW, height, PPE) is used. 5) Copy D/E into Observations tracker.
B9: CAPA-ID | C9: RAW NOTES (input) | D9: FORMATTED EHS OBSERVATION (output) | E9: CAPA — Corrective & Preventive Action (output) | F9: Suggested Type | G9: Suggested Severity | H9: Push status
B10: CAPA-001 | C10: guys working on roof no harness and edge open next to boiler | D10: =IF(C10="","",IF(SUMPRODUCT(--ISNUMBER(SEARCH({"lift","crane","sling","rigging"},LOWER(C10))))>0,"EHS Observation — Lifting Operations: Unsafe lifting practice observed. Load control / exclusion zone / lifting gear integrity not in accordance with project lifting procedure and PTW conditions. Immediate stop-work required until a documented lift plan and competent rigger/banksman are in place.",IF(SUMPRODUCT(--ISNUMBER(SEARCH({"scaffold","toeboard","tag"},LOWER(C10))))>0,"EHS Observation — Scaffolding: Scaffold does not meet TG20/project standard (incomplete components / incorrect tagging). Scaffold shall be red-tagged and access prohibited until inspected by a competent scaffolder.",IF(SUMPRODUCT(--ISNUMBER(SEARCH({"excav","trench","shoring"},LOWER(C10))))>0,"EHS Observation — Excavation: Excavation controls (shoring/battering, access, spoil distance, underground services) are not adequately implemented. Work shall stop until a CAT-scan, permit and shoring design are verified.",IF(SUMPRODUCT(--ISNUMBER(SEARCH({"confined","tank","vessel","gas test"},LOWER(C10))))>0,"EHS Observation — Confined Space: Entry without atmospheric testing and attendant is a critical violation of the confined space procedure. Evacuate, isolate, gas-test and re-issue PTW before any re-entry.",IF(SUMPRODUCT(--ISNUMBER(SEARCH({"harness","height","edge","roof","ladder"},LOWER(C10))))>0,"EHS Observation — Working at Height: Personnel exposed to an unprotected edge / without 100% tie-off. This is a life-saving rule breach. Stop work, establish exclusion, install collective protection and verified anchorage.",IF(SUMPRODUCT(--ISNUMBER(SEARCH({"electrical","cable","live","loto","11kv"},LOWER(C10))))>0,"EHS Observation — Electrical: Work adjacent to live services without isolation/LOTO, barriers and a dedicated spotter. Energy isolation certificate and PTW must be in place before restart.",IF(SUMPRODUCT(--ISNUMBER(SEARCH({"ptw","permit"},LOWER(C10))))>0,"EHS Observation — Work Permit: Activity ongoing with missing, expired or uncontrolled PTW. All work shall cease until a valid permit is issued, briefed and displayed at the workface.","EHS Observation: Unsafe act/condition identified on KAZ PP Expansion Project. The practice does not comply with the Project HSE Plan and applicable procedure. Stop and make safe; record in the observation tracker; assign owner and close-out date.")))))))) | E10: =IF(C10="","","1) CORRECTIVE: Stop work and make the area immediately safe; remove at-risk personnel. "&"2) CONTAINMENT: Barricade, tag-out defective equipment, withdraw PTW if invalid. "&"3) PREVENTIVE: Toolbox talk to the crew within 24h; competency verification; update JSA/lift plan; "&"supervision presence increased for 72h; consider NCR if life-saving rule breached. "&"4) VERIFY: EHS inspection before restart; close observation only with evidence (photo + signature).") | F10: =IF(C10="","",IF(SUMPRODUCT(--ISNUMBER(SEARCH({"lift","crane","sling"},LOWER(C10))))>0,"Lifting Operations",IF(SUMPRODUCT(--ISNUMBER(SEARCH({"scaffold"},LOWER(C10))))>0,"Scaffolding",IF(SUMPRODUCT(--ISNUMBER(SEARCH({"excav","trench"},LOWER(C10))))>0,"Excavation",IF(SUMPRODUCT(--ISNUMBER(SEARCH({"confined","tank","gas test"},LOWER(C10))))>0,"Confined Space",IF(SUMPRODUCT(--ISNUMBER(SEARCH({"height","harness","roof","edge"},LOWER(C10))))>0,"Working at Height",IF(SUMPRODUCT(--ISNUMBER(SEARCH({"electrical","cable","loto"},LOWER(C10))))>0,"Electrical",IF(SUMPRODUCT(--ISNUMBER(SEARCH({"ptw","permit"},LOWER(C10))))>0,"Work Permits / PTW","Other"))))))) | G10: =IF(C10="","",IF(SUMPRODUCT(--ISNUMBER(SEARCH({"confined","live","11kv","unprotected edge","no harness","no gas"},LOWER(C10))))>0,"Critical",IF(SUMPRODUCT(--ISNUMBER(SEARCH({"scaffold","excav","lift","electrical","ptw"},LOWER(C10))))>0,"High","Medium"))) | H10: Draft
B11: CAPA-002 | C11: excavator digging beside live 11kv cable no spotter ptw not on site | D11: =IF(C11="","",IF(SUMPRODUCT(--ISNUMBER(SEARCH({"lift","crane","sling","rigging"},LOWER(C11))))>0,"EHS Observation — Lifting Operations: Unsafe lifting practice observed. Load control / exclusion zone / lifting gear integrity not in accordance with project lifting procedure and PTW conditions. Immediate stop-work required until a documented lift plan and competent rigger/banksman are in place.",IF(SUMPRODUCT(--ISNUMBER(SEARCH({"scaffold","toeboard","tag"},LOWER(C11))))>0,"EHS Observation — Scaffolding: Scaffold does not meet TG20/project standard (incomplete components / incorrect tagging). Scaffold shall be red-tagged and access prohibited until inspected by a competent scaffolder.",IF(SUMPRODUCT(--ISNUMBER(SEARCH({"excav","trench","shoring"},LOWER(C11))))>0,"EHS Observation — Excavation: Excavation controls (shoring/battering, access, spoil distance, underground services) are not adequately implemented. Work shall stop until a CAT-scan, permit and shoring design are verified.",IF(SUMPRODUCT(--ISNUMBER(SEARCH({"confined","tank","vessel","gas test"},LOWER(C11))))>0,"EHS Observation — Confined Space: Entry without atmospheric testing and attendant is a critical violation of the confined space procedure. Evacuate, isolate, gas-test and re-issue PTW before any re-entry.",IF(SUMPRODUCT(--ISNUMBER(SEARCH({"harness","height","edge","roof","ladder"},LOWER(C11))))>0,"EHS Observation — Working at Height: Personnel exposed to an unprotected edge / without 100% tie-off. This is a life-saving rule breach. Stop work, establish exclusion, install collective protection and verified anchorage.",IF(SUMPRODUCT(--ISNUMBER(SEARCH({"electrical","cable","live","loto","11kv"},LOWER(C11))))>0,"EHS Observation — Electrical: Work adjacent to live services without isolation/LOTO, barriers and a dedicated spotter. Energy isolation certificate and PTW must be in place before restart.",IF(SUMPRODUCT(--ISNUMBER(SEARCH({"ptw","permit"},LOWER(C11))))>0,"EHS Observation — Work Permit: Activity ongoing with missing, expired or uncontrolled PTW. All work shall cease until a valid permit is issued, briefed and displayed at the workface.","EHS Observation: Unsafe act/condition identified on KAZ PP Expansion Project. The practice does not comply with the Project HSE Plan and applicable procedure. Stop and make safe; record in the observation tracker; assign owner and close-out date.")))))))) | E11: =IF(C11="","","1) CORRECTIVE: Stop work and make the area immediately safe; remove at-risk personnel. "&"2) CONTAINMENT: Barricade, tag-out defective equipment, withdraw PTW if invalid. "&"3) PREVENTIVE: Toolbox talk to the crew within 24h; competency verification; update JSA/lift plan; "&"supervision presence increased for 72h; consider NCR if life-saving rule breached. "&"4) VERIFY: EHS inspection before restart; close observation only with evidence (photo + signature).") | F11: =IF(C11="","",IF(SUMPRODUCT(--ISNUMBER(SEARCH({"lift","crane","sling"},LOWER(C11))))>0,"Lifting Operations",IF(SUMPRODUCT(--ISNUMBER(SEARCH({"scaffold"},LOWER(C11))))>0,"Scaffolding",IF(SUMPRODUCT(--ISNUMBER(SEARCH({"excav","trench"},LOWER(C11))))>0,"Excavation",IF(SUMPRODUCT(--ISNUMBER(SEARCH({"confined","tank","gas test"},LOWER(C11))))>0,"Confined Space",IF(SUMPRODUCT(--ISNUMBER(SEARCH({"height","harness","roof","edge"},LOWER(C11))))>0,"Working at Height",IF(SUMPRODUCT(--ISNUMBER(SEARCH({"electrical","cable","loto"},LOWER(C11))))>0,"Electrical",IF(SUMPRODUCT(--ISNUMBER(SEARCH({"ptw","permit"},LOWER(C11))))>0,"Work Permits / PTW","Other"))))))) | G11: =IF(C11="","",IF(SUMPRODUCT(--ISNUMBER(SEARCH({"confined","live","11kv","unprotected edge","no harness","no gas"},LOWER(C11))))>0,"Critical",IF(SUMPRODUCT(--ISNUMBER(SEARCH({"scaffold","excav","lift","electrical","ptw"},LOWER(C11))))>0,"High","Medium"))) | H11: Draft
B12: CAPA-003 | C12: sling colour code expired and tag line missing tandem lift | D12: =IF(C12="","",IF(SUMPRODUCT(--ISNUMBER(SEARCH({"lift","crane","sling","rigging"},LOWER(C12))))>0,"EHS Observation — Lifting Operations: Unsafe lifting practice observed. Load control / exclusion zone / lifting gear integrity not in accordance with project lifting procedure and PTW conditions. Immediate stop-work required until a documented lift plan and competent rigger/banksman are in place.",IF(SUMPRODUCT(--ISNUMBER(SEARCH({"scaffold","toeboard","tag"},LOWER(C12))))>0,"EHS Observation — Scaffolding: Scaffold does not meet TG20/project standard (incomplete components / incorrect tagging). Scaffold shall be red-tagged and access prohibited until inspected by a competent scaffolder.",IF(SUMPRODUCT(--ISNUMBER(SEARCH({"excav","trench","shoring"},LOWER(C12))))>0,"EHS Observation — Excavation: Excavation controls (shoring/battering, access, spoil distance, underground services) are not adequately implemented. Work shall stop until a CAT-scan, permit and shoring design are verified.",IF(SUMPRODUCT(--ISNUMBER(SEARCH({"confined","tank","vessel","gas test"},LOWER(C12))))>0,"EHS Observation — Confined Space: Entry without atmospheric testing and attendant is a critical violation of the confined space procedure. Evacuate, isolate, gas-test and re-issue PTW before any re-entry.",IF(SUMPRODUCT(--ISNUMBER(SEARCH({"harness","height","edge","roof","ladder"},LOWER(C12))))>0,"EHS Observation — Working at Height: Personnel exposed to an unprotected edge / without 100% tie-off. This is a life-saving rule breach. Stop work, establish exclusion, install collective protection and verified anchorage.",IF(SUMPRODUCT(--ISNUMBER(SEARCH({"electrical","cable","live","loto","11kv"},LOWER(C12))))>0,"EHS Observation — Electrical: Work adjacent to live services without isolation/LOTO, barriers and a dedicated spotter. Energy isolation certificate and PTW must be in place before restart.",IF(SUMPRODUCT(--ISNUMBER(SEARCH({"ptw","permit"},LOWER(C12))))>0,"EHS Observation — Work Permit: Activity ongoing with missing, expired or uncontrolled PTW. All work shall cease until a valid permit is issued, briefed and displayed at the workface.","EHS Observation: Unsafe act/condition identified on KAZ PP Expansion Project. The practice does not comply with the Project HSE Plan and applicable procedure. Stop and make safe; record in the observation tracker; assign owner and close-out date.")))))))) | E12: =IF(C12="","","1) CORRECTIVE: Stop work and make the area immediately safe; remove at-risk personnel. "&"2) CONTAINMENT: Barricade, tag-out defective equipment, withdraw PTW if invalid. "&"3) PREVENTIVE: Toolbox talk to the crew within 24h; competency verification; update JSA/lift plan; "&"supervision presence increased for 72h; consider NCR if life-saving rule breached. "&"4) VERIFY: EHS inspection before restart; close observation only with evidence (photo + signature).") | F12: =IF(C12="","",IF(SUMPRODUCT(--ISNUMBER(SEARCH({"lift","crane","sling"},LOWER(C12))))>0,"Lifting Operations",IF(SUMPRODUCT(--ISNUMBER(SEARCH({"scaffold"},LOWER(C12))))>0,"Scaffolding",IF(SUMPRODUCT(--ISNUMBER(SEARCH({"excav","trench"},LOWER(C12))))>0,"Excavation",IF(SUMPRODUCT(--ISNUMBER(SEARCH({"confined","tank","gas test"},LOWER(C12))))>0,"Confined Space",IF(SUMPRODUCT(--ISNUMBER(SEARCH({"height","harness","roof","edge"},LOWER(C12))))>0,"Working at Height",IF(SUMPRODUCT(--ISNUMBER(SEARCH({"electrical","cable","loto"},LOWER(C12))))>0,"Electrical",IF(SUMPRODUCT(--ISNUMBER(SEARCH({"ptw","permit"},LOWER(C12))))>0,"Work Permits / PTW","Other"))))))) | G12: =IF(C12="","",IF(SUMPRODUCT(--ISNUMBER(SEARCH({"confined","live","11kv","unprotected edge","no harness","no gas"},LOWER(C12))))>0,"Critical",IF(SUMPRODUCT(--ISNUMBER(SEARCH({"scaffold","excav","lift","electrical","ptw"},LOWER(C12))))>0,"High","Medium"))) | H12: Draft
